File: Specimen_RawData_3.csv
Time,Extension,Load
(s),(mm),(N)
"0.00000","0.00000","0.04450"
"0.10000","-0.01270","0.01354"
"0.20000","-0.04989","0.01658"
"0.30000","-0.08328","0.00408"
"0.40000","-0.11672","0.01633"
"0.50000","-0.15006","0.01816"
"0.60000","-0.18347","0.01363"
"0.70000","-0.21696","0.03140"
"0.80000","-0.25016","0.02959"
"0.90000","-0.28356","0.01042"
"1.00000","-0.31677","0.01757"
"1.10000","-0.35033","0.02835"
"1.20000","-0.38357","0.03149"
"1.30000","-0.41704","0.03260"
"1.40000","-0.45018","0.02374"
"1.50000","-0.48362","0.03412"
"1.60000","-0.51683","0.03009"
"1.70000","-0.55041","0.02952"
"1.80000","-0.58367","0.02838"
"1.90000","-0.61699","0.03243"
"2.00000","-0.65028","0.01996"
"2.10000","-0.68356","0.02098"
"2.20000","-0.71702","0.02988"
"2.30000","-0.75035","0.01902"
"2.40000","-0.78361","0.02340"
"2.50000","-0.81675","0.01440"
"2.60000","-0.85035","0.00809"
"2.70000","-0.88352","0.01803"
"2.80000","-0.91706","0.01600"
"2.90000","-0.95014","0.01718"
"3.00000","-0.98351","0.01981"
"3.10000","-1.01673","0.01510"
"3.20000","-1.05031","0.02215"
"3.30000","-1.08359","0.01426"
"3.40000","-1.11692","0.01327"
"3.50000","-1.15008","0.01576"
"3.60000","-1.18346","0.01936"
"3.70000","-1.21685","-0.00062"
"3.80000","-1.25019","-0.02197"
"3.90000","-1.28356","-0.03386"
"4.00000","-1.31661","-0.03419"
"4.10000","-1.35011","-0.05458"
"4.20000","-1.38331","-0.08564"
"4.30000","-1.41705","-0.09937"
"4.40000","-1.45012","-0.10931"
"4.50000","-1.48348","-0.10025"
"4.60000","-1.51675","-0.10072"
"4.70000","-1.55026","-0.11344"
"4.80000","-1.58364","-0.12613"
"4.90000","-1.61692","-0.12809"
"5.00000","-1.65014","-0.13474"
"5.10000","-1.68348","-0.13781"
"5.20000","-1.71692","-0.12783"
"5.30000","-1.75029","-0.13953"
"5.40000","-1.78374","-0.13852"
"5.50000","-1.81687","-0.14953"
"5.60000","-1.85027","-0.14911"
"5.70000","-1.88348","-0.15688"
"5.80000","-1.91711","-0.16346"
"5.90000","-1.95024","-0.17118"
"6.00000","-1.98364","-0.17293"
"6.10000","-2.01683","-0.18750"
"6.20000","-2.05032","-0.19391"
"6.30000","-2.08361","-0.20500"
"6.40000","-2.11708","-0.21285"
"6.50000","-2.15023","-0.22321"
"6.60000","-2.18351","-0.22209"
"6.70000","-2.21693","-0.22969"
"6.80000","-2.25018","-0.24040"
"6.90000","-2.28368","-0.23461"
"7.00000","-2.31677","-0.24363"
"7.10000","-2.35022","-0.25282"
"7.20000","-2.38339","-0.25647"
"7.30000","-2.41704","-0.25983"
"7.40000","-2.45022","-0.26631"
"7.50000","-2.48357","-0.27036"
"7.60000","-2.51670","-0.28137"
"7.70000","-2.55021","-0.28818"
"7.80000","-2.58343","-0.27887"
"7.90000","-2.61694","-0.29258"
"8.00000","-2.65015","-0.29494"
"8.10000","-2.68333","-0.30767"
"8.20000","-2.71680","-0.31902"
"8.30000","-2.75008","-0.32072"
"8.40000","-2.78373","-0.30881"
"8.50000","-2.81672","-0.31995"
"8.60000","-2.85017","-0.31214"
"8.70000","-2.88334","-0.32247"
"8.80000","-2.91699","-0.31609"
"8.90000","-2.95025","-0.30108"
"9.00000","-2.98366","-0.30380"
"9.10000","-3.01677","-0.30228"
"9.20000","-3.05024","-0.30847"
"9.30000","-3.08352","-0.31228"
"9.40000","-3.11708","-0.30735"
"9.50000","-3.15026","-0.30600"
"9.60000","-3.18358","-0.30975"
"9.70000","-3.21691","-0.31922"
"9.80000","-3.25019","-0.31326"
"9.90000","-3.28377","-0.31004"
"10.00000","-3.31692","-0.31382"
"10.10000","-3.35031","-0.31758"
"10.20000","-3.38345","-0.33283"
"10.30000","-3.41698","-0.32900"
"10.40000","-3.45018","-0.33244"
"10.50000","-3.48379","-0.33265"
"10.60000","-3.51677","-0.34066"
"10.70000","-3.55022","-0.34532"
"10.80000","-3.58358","-0.32757"
"10.90000","-3.61695","-0.33603"
"11.00000","-3.65030","-0.33930"
"11.10000","-3.68351","-0.33728"
"11.20000","-3.71676","-0.35369"
"11.30000","-3.75007","-0.35046"
"11.40000","-3.78366","-0.35040"
"11.50000","-3.81686","-0.35469"
"11.60000","-3.85029","-0.34362"
"11.70000","-3.88330","-0.35741"
"11.80000","-3.91691","-0.35754"
"11.90000","-3.95008","-0.35900"
"12.00000","-3.98363","-0.36494"
"12.10000","-4.01671","-0.36174"
"12.20000","-4.05007","-0.36662"
"12.30000","-4.08339","-0.34686"
"12.40000","-4.11682","-0.34631"
"12.50000","-4.15032","-0.35466"
"12.60000","-4.18353","-0.35057"
"12.70000","-4.21686","-0.35821"
"12.80000","-4.25007","-0.34955"
"12.90000","-4.28361","-0.34490"
"13.00000","-4.31692","-0.34269"
"13.10000","-4.35035","-0.35957"
"13.20000","-4.38340","-0.37419"
"13.30000","-4.41694","-0.36066"
"13.40000","-4.45015","-0.35853"
"13.50000","-4.48379","-0.35797"
"13.60000","-4.51692","-0.37512"
"13.70000","-4.55034","-0.38172"
"13.80000","-4.58346","-0.38216"
"13.90000","-4.61689","-0.37337"
"14.00000","-4.65040","-0.37063"
"14.10000","-4.68366","-0.37575"
"14.20000","-4.71696","-0.39274"
"14.30000","-4.75014","-0.39801"
"14.40000","-4.78365","-0.39650"
"14.50000","-4.81682","-0.40111"
"14.60000","-4.85045","-0.39053"
"14.70000","-4.88337","-0.41015"
"14.80000","-4.91691","-0.41734"
"14.90000","-4.95011","-0.41237"
"15.00000","-4.98372","-0.41099"
"15.10000","-5.01688","-0.40785"
"15.20000","-5.05027","-0.43219"
"15.30000","-5.08338","-0.43114"
"15.40000","-5.11691","-0.43645"
"15.50000","-5.15027","-0.43098"
"15.60000","-5.18360","-0.43024"
"15.70000","-5.21684","-0.44779"
"15.80000","-5.25003","-0.45667"
"15.90000","-5.28350","-0.44685"
"16.00000","-5.31674","-0.45436"
"16.10000","-5.35034","-0.45410"
"16.20000","-5.38338","-0.45479"
"16.30000","-5.41683","-0.45742"
"16.40000","-5.45003","-0.44967"
"16.50000","-5.48363","-0.45118"
"16.60000","-5.51681","-0.45772"
"16.70000","-5.55009","-0.46651"
"16.80000","-5.58344","-0.47118"
"16.90000","-5.61686","-0.47451"
"17.00000","-5.65020","-0.47322"
"17.10000","-5.68365","-0.46916"
"17.20000","-5.71702","-0.48406"
"17.30000","-5.75010","-0.48811"
"17.40000","-5.78364","-0.49519"
"17.50000","-5.81678","-0.49526"
"17.60000","-5.85047","-0.48519"
"17.70000","-5.88352","-0.50082"
"17.80000","-5.91701","-0.51050"
"17.90000","-5.95008","-0.51609"
"18.00000","-5.98365","-0.51615"
"18.10000","-6.01696","-0.51120"
"18.20000","-6.05037","-0.50911"
"18.30000","-6.08355","-0.51500"
"18.40000","-6.11686","-0.51381"
"18.50000","-6.15031","-0.51432"
"18.60000","-6.18361","-0.51719"
"18.70000","-6.21708","-0.52656"
"18.80000","-6.25005","-0.52197"
"18.90000","-6.28358","-0.52413"
"19.00000","-6.31680","-0.51784"
"19.10000","-6.35033","-0.52324"
"19.20000","-6.38349","-0.53415"
"19.30000","-6.41693","-0.54384"
"19.40000","-6.44994","-0.54618"
"19.50000","-6.48355","-0.54300"
"19.60000","-6.51689","-0.53253"
"19.70000","-6.55029","-0.49405"
"19.80000","-6.58348","-0.46703"
"19.90000","-6.61669","-0.47170"
"20.00000","-6.65013","-0.46231"
"20.10000","-6.68344","-0.46032"
"20.20000","-6.71697","-0.46017"
"20.30000","-6.75009","-0.45711"
"20.40000","-6.78342","-0.45808"
"20.50000","-6.81669","-0.46472"
"20.60000","-6.85025","-0.46075"
"20.70000","-6.88358","-0.47869"
"20.80000","-6.91698","-0.48635"
"20.90000","-6.95005","-0.48792"
"21.00000","-6.98359","-0.48128"
"21.10000","-7.01682","-0.48673"
"21.20000","-7.05043","-0.48434"
"21.30000","-7.08363","-0.49198"
"21.40000","-7.11684","-0.48106"
"21.50000","-7.15027","-0.47347"
"21.60000","-7.18359","-0.46612"
"21.70000","-7.21711","-0.46246"
"21.80000","-7.25019","-0.46283"
"21.90000","-7.28367","-0.45348"
"22.00000","-7.31674","-0.45746"
"22.10000","-7.35030","-0.44635"
"22.20000","-7.38365","-0.44754"
"22.30000","-7.41705","-0.46065"
"22.40000","-7.45018","-0.46112"
"22.50000","-7.48358","-0.47241"
"22.60000","-7.51681","-0.46530"
"22.70000","-7.55033","-0.46811"
"22.80000","-7.58367","-0.46692"
"22.90000","-7.61683","-0.47728"
"23.00000","-7.65018","-0.47519"
"23.10000","-7.68353","-0.47592"
"23.20000","-7.71696","-0.48261"
"23.30000","-7.75020","-0.48294"
"23.40000","-7.78357","-0.48841"
"23.50000","-7.81656","-0.48572"
"23.60000","-7.85020","-0.47380"
"23.70000","-7.88343","-0.47319"
"23.80000","-7.91700","-0.48156"
"23.90000","-7.95008","-0.48423"
"24.00000","-7.98348","-0.49421"
"24.10000","-8.01672","-0.49024"
"24.20000","-8.05025","-0.48915"
"24.30000","-8.08355","-0.49579"
"24.40000","-8.11682","-0.50419"
"24.50000","-8.15009","-0.49949"
"24.60000","-8.18342","-0.49772"
"24.70000","-8.21692","-0.49985"
"24.80000","-8.25031","-0.50703"
"24.90000","-8.28367","-0.51087"
"25.00000","-8.31673","-0.51337"
"25.10000","-8.35032","-0.50948"
"25.20000","-8.38346","-0.52298"
"25.30000","-8.41717","-0.52884"
"25.40000","-8.45021","-0.53522"
"25.50000","-8.48357","-0.52224"
"25.60000","-8.51686","-0.51976"
"25.70000","-8.55035","-0.52767"
"25.80000","-8.58370","-0.53345"
"25.90000","-8.61699","-0.53509"
"26.00000","-8.65026","-0.52904"
"26.10000","-8.68350","-0.52964"
"26.20000","-8.71690","-0.51765"
"26.30000","-8.75033","-0.50898"
"26.40000","-8.78368","-0.50621"
"26.50000","-8.81681","-0.51828"
"26.60000","-8.85028","-0.51099"
"26.70000","-8.88347","-0.49422"
"26.80000","-8.91700","-0.50198"
"26.90000","-8.95026","-0.51096"
"27.00000","-8.98355","-0.51694"
"27.10000","-9.01670","-0.51742"
"27.20000","-9.05022","-0.51515"
"27.30000","-9.08357","-0.51901"
"27.40000","-9.11694","-0.52776"
"27.50000","-9.15016","-0.53896"
"27.60000","-9.18331","-0.52964"
"27.70000","-9.21687","-0.52412"
"27.80000","-9.25014","-0.51658"
"27.90000","-9.28366","-0.52101"
"28.00000","-9.31673","-0.52268"
"28.10000","-9.35017","-0.50693"
"28.20000","-9.38330","-0.49874"
"28.30000","-9.41701","-0.49706"
"28.40000","-9.45016","-0.49967"
"28.50000","-9.48363","-0.50664"
"28.60000","-9.51671","-0.50462"
"28.70000","-9.55016","-0.49387"
"28.80000","-9.58353","-0.48706"
"28.90000","-9.61703","-0.48414"
"29.00000","-9.65027","-0.48117"
"29.10000","-9.68350","-0.49208"
"29.20000","-9.71694","-0.49886"
"29.30000","-9.75017","-0.50226"
"29.40000","-9.78378","-0.51311"
"29.50000","-9.81686","-0.52401"
"29.60000","-9.85026","-0.51533"
"29.70000","-9.88346","-0.52012"
"29.80000","-9.91700","-0.52887"
"29.90000","-9.95031","-0.52984"
"30.00000","-9.98375","-0.53673"
"30.10000","-10.01685","-0.53663"
"30.20000","-10.05024","-0.52953"
"30.30000","-10.08351","-0.53524"
"30.40000","-10.11705","-0.54043"
"30.50000","-10.15032","-0.55507"
"30.60000","-10.18353","-0.55914"
"30.70000","-10.21686","-0.54208"
"30.80000","-10.25015","-0.54111"
"30.90000","-10.28369","-0.55070"
"31.00000","-10.31688","-0.55224"
"31.10000","-10.35024","-0.55277"
"31.20000","-10.38336","-0.54598"
"31.30000","-10.41696","-0.53249"
"31.40000","-10.45014","-0.53971"
"31.50000","-10.48362","-0.55075"
"31.60000","-10.51671","-0.55202"
"31.70000","-10.55010","-0.54203"
"31.80000","-10.58342","-0.54082"
"31.90000","-10.61689","-0.54013"
"32.00000","-10.65028","-0.54394"
"32.10000","-10.68345","-0.54777"
"32.20000","-10.71677","-0.54263"
"32.30000","-10.75002","-0.53937"
"32.40000","-10.78355","-0.53750"
"32.50000","-10.81680","-0.53408"
"32.60000","-10.85021","-0.52951"
"32.70000","-10.88338","-0.53136"
"32.80000","-10.91689","-0.52611"
"32.90000","-10.95014","-0.53337"
"33.00000","-10.98382","-0.52748"
"33.10000","-11.01685","-0.52441"
"33.20000","-11.05023","-0.52890"
"33.30000","-11.08354","-0.52089"
"33.40000","-11.11699","-0.52352"
"33.50000","-11.15040","-0.52772"
"33.60000","-11.18363","-0.52154"
"33.70000","-11.21686","-0.53202"
"33.80000","-11.25018","-0.52830"
"33.90000","-11.28374","-0.53132"
"34.00000","-11.31695","-0.52656"
"34.10000","-11.35037","-0.53534"
"34.20000","-11.38344","-0.54756"
"34.30000","-11.41695","-0.54735"
"34.40000","-11.45011","-0.55141"
"34.50000","-11.48377","-0.55675"
"34.60000","-11.51682","-0.55014"
"34.70000","-11.55025","-0.55110"
"34.80000","-11.58352","-0.55179"
"34.90000","-11.61685","-0.54460"
"35.00000","-11.65026","-0.55383"
"35.10000","-11.68358","-0.55802"
"35.20000","-11.71683","-0.54934"
"35.30000","-11.75003","-0.53700"
"35.40000","-11.78362","-0.55178"
"35.50000","-11.81677","-0.55760"
"35.60000","-11.85030","-0.56360"
"35.70000","-11.88335","-0.56858"
"35.80000","-11.91678","-0.55927"
"35.90000","-11.95000","-0.56655"
"36.00000","-11.98355","-0.57074"
"36.10000","-12.01682","-0.57669"
"36.20000","-12.05023","-0.59407"
"36.30000","-12.08336","-0.59504"
"36.40000","-12.11681","-0.60040"
"36.50000","-12.15024","-0.60821"
"36.60000","-12.18359","-0.61626"
"36.70000","-12.21689","-0.62453"
"36.80000","-12.25005","-0.61950"
"36.90000","-12.28355","-0.62478"
"37.00000","-12.31679","-0.62705"
"37.10000","-12.35046","-0.63893"
"37.20000","-12.38351","-0.64166"
"37.30000","-12.41696","-0.63307"
"37.40000","-12.45019","-0.63420"
"37.50000","-12.48370","-0.64136"
"37.60000","-12.51702","-0.64062"
"37.70000","-12.55040","-0.64090"
"37.80000","-12.58347","-0.63389"
"37.90000","-12.61691","-0.61719"
"38.00000","-12.65033","-0.61191"
"38.10000","-12.68371","-0.61310"
"38.20000","-12.71698","-0.61235"
"38.30000","-12.75020","-0.61510"
"38.40000","-12.78362","-0.61043"
"38.50000","-12.81680","-0.60846"
"38.60000","-12.85038","-0.60678"
"38.70000","-12.88343","-0.60891"
"38.80000","-12.91693","-0.59205"
"38.90000","-12.95003","-0.58434"
"39.00000","-12.98363","-0.58118"
"39.10000","-13.01689","-0.57743"
"39.20000","-13.05040","-0.58597"
"39.30000","-13.08344","-0.59549"
"39.40000","-13.11672","-0.58708"
"39.50000","-13.15024","-0.58475"
"39.60000","-13.18352","-0.58442"
"39.70000","-13.21691","-0.58845"
"39.80000","-13.25006","-0.58586"
"39.90000","-13.28340","-0.59189"
"40.00000","-13.31666","-0.58966"
"40.10000","-13.35028","-0.58421"
"40.20000","-13.38344","-0.59304"
"40.30000","-13.41690","-0.58576"
"40.40000","-13.44996","-0.59461"
"40.50000","-13.48350","-0.58980"
"40.60000","-13.51682","-0.58354"
"40.70000","-13.55038","-0.58680"
"40.80000","-13.58348","-0.57683"
"40.90000","-13.61680","-0.58438"
"41.00000","-13.65022","-0.58647"
"41.10000","-13.68360","-0.58307"
"41.20000","-13.71710","-0.58757"
"41.30000","-13.75021","-0.58050"
"41.40000","-13.78359","-0.58389"
"41.50000","-13.81685","-0.59376"
"41.60000","-13.85034","-0.58885"
"41.70000","-13.88366","-0.59539"
"41.80000","-13.91704","-0.59083"
"41.90000","-13.95012","-0.60211"
"42.00000","-13.98368","-0.59116"
"42.10000","-14.01689","-0.60396"
"42.20000","-14.05043","-0.60615"
"42.30000","-14.08360","-0.60695"
"42.40000","-14.11687","-0.61037"
"42.50000","-14.15022","-0.59933"
"42.60000","-14.18349","-0.59384"
"42.70000","-14.21710","-0.60585"
"42.80000","-14.25021","-0.59698"
"42.90000","-14.28356","-0.59001"
"43.00000","-14.31668","-0.59524"
"43.10000","-14.35030","-0.58628"
"43.20000","-14.38347","-0.59185"
"43.30000","-14.41701","-0.58744"
"43.40000","-14.45002","-0.59110"
"43.50000","-14.48354","-0.59756"
"43.60000","-14.51677","-0.59452"
"43.70000","-14.55025","-0.60715"
"43.80000","-14.58353","-0.60370"
"43.90000","-14.61675","-0.60863"
"44.00000","-14.65005","-0.60552"
"44.10000","-14.68340","-0.60550"
"44.20000","-14.71690","-0.60602"
"44.30000","-14.75013","-0.61206"
"44.40000","-14.78356","-0.61947"
"44.50000","-14.81662","-0.62397"
"44.60000","-14.85019","-0.62343"
"44.70000","-14.88342","-0.62074"
"44.80000","-14.91705","-0.60995"
"44.90000","-14.95014","-0.61324"
"45.00000","-14.98353","-0.61051"
"45.10000","-15.01680","-0.61216"
"45.20000","-15.05033","-0.61852"
"45.30000","-15.08373","-0.61766"
"45.40000","-15.11698","-0.61486"
"45.50000","-15.15027","-0.62472"
"45.60000","-15.18357","-0.61301"
"45.70000","-15.21702","-0.61647"
"45.80000","-15.25035","-0.61546"
"45.90000","-15.28373","-0.61602"
"46.00000","-15.31672","-0.62997"
"46.10000","-15.35036","-0.62141"
"46.20000","-15.38351","-0.63523"
"46.30000","-15.41710","-0.63864"
"46.40000","-15.45018","-0.64150"
"46.50000","-15.48361","-0.64231"
"46.60000","-15.51675","-0.64631"
"46.70000","-15.55021","-0.64959"
"46.80000","-15.58367","-0.63927"
"46.90000","-15.61690","-0.64501"
"47.00000","-15.65018","-0.64743"
"47.10000","-15.68345","-0.64005"
"47.20000","-15.71697","-0.64732"
"47.30000","-15.75026","-0.65350"
"47.40000","-15.78370","-0.64952"
"47.50000","-15.81668","-0.65403"
"47.60000","-15.85018","-0.66146"
"47.70000","-15.88343","-0.65924"
"47.80000","-15.91700","-0.66000"
"47.90000","-15.95011","-0.66412"
"48.00000","-15.98347","-0.66813"
"48.10000","-16.01666","-0.66550"
"48.20000","-16.05012","-0.68215"
"48.30000","-16.08354","-0.67474"
"48.40000","-16.11683","-0.68385"
"48.50000","-16.15004","-0.68461"
"48.60000","-16.18324","-0.67257"
"48.70000","-16.21685","-0.66789"
"48.80000","-16.25016","-0.66661"
"48.90000","-16.28371","-0.67525"
"49.00000","-16.31682","-0.67854"
"49.10000","-16.35023","-0.67224"
"49.20000","-16.38344","-0.67776"
"49.30000","-16.41704","-0.66756"
"49.40000","-16.45033","-0.66938"
"49.50000","-16.48365","-0.66872"
"49.60000","-16.51681","-0.67329"
"49.70000","-16.55038","-0.67054"
"49.80000","-16.58364","-0.67610"
"49.90000","-16.61711","-0.67838"
"50.00000","-16.65041","-0.68138"
"50.10000","-16.68342","-0.68294"
"50.20000","-16.71696","-0.68457"
"50.30000","-16.75022","-0.69526"
"50.40000","-16.78380","-0.68587"
"50.50000","-16.81686","-0.68913"
"50.60000","-16.85028","-0.67327"
"50.70000","-16.88340","-0.68692"
"50.80000","-16.91689","-0.68120"
"50.90000","-16.95028","-0.67473"
"51.00000","-16.98363","-0.67787"
"51.10000","-17.01679","-0.67892"
"51.20000","-17.05018","-0.67935"
"51.30000","-17.08352","-0.68111"
"51.40000","-17.11692","-0.67774"
"51.50000","-17.15032","-0.67516"
"51.60000","-17.18337","-0.67544"
"51.70000","-17.21680","-0.67006"
"51.80000","-17.25009","-0.67496"
"51.90000","-17.28358","-0.66951"
"52.00000","-17.31673","-0.67841"
"52.10000","-17.35010","-0.67731"
"52.20000","-17.38325","-0.67573"
"52.30000","-17.41678","-0.68322"
"52.40000","-17.45007","-0.68696"
"52.50000","-17.48360","-0.69132"
"52.60000","-17.51679","-0.68498"
"52.70000","-17.55013","-0.68052"
"52.80000","-17.58346","-0.67183"
"52.90000","-17.61695","-0.66643"
"53.00000","-17.65036","-0.66136"
"53.10000","-17.68352","-0.66610"
"53.20000","-17.71694","-0.66423"
"53.30000","-17.75015","-0.66438"
"53.40000","-17.78368","-0.66678"
"53.50000","-17.81706","-0.67734"
"53.60000","-17.85038","-0.68215"
"53.70000","-17.88341","-0.68384"
"53.80000","-17.91701","-0.67446"
"53.90000","-17.95023","-0.67314"
"54.00000","-17.98387","-0.66958"
"54.10000","-18.01698","-0.67383"
"54.20000","-18.05022","-0.68755"
"54.30000","-18.08360","-0.68306"
"54.40000","-18.11696","-0.68440"
"54.50000","-18.15043","-0.68076"
"54.60000","-18.18359","-0.67368"
"54.70000","-18.21693","-0.67829"
"54.80000","-18.25010","-0.66985"
"54.90000","-18.28361","-0.66896"
"55.00000","-18.31693","-0.67356"
"55.10000","-18.35029","-0.67424"
"55.20000","-18.38337","-0.68501"
"55.30000","-18.41687","-0.67625"
"55.40000","-18.45011","-0.67457"
"55.50000","-18.48363","-0.67946"
"55.60000","-18.51686","-0.68465"
"55.70000","-18.55015","-0.69247"
"55.80000","-18.58339","-0.70430"
"55.90000","-18.61684","-0.69563"
"56.00000","-18.65023","-0.68523"
"56.10000","-18.68344","-0.68995"
"56.20000","-18.71676","-0.71176"
"56.30000","-18.74998","-0.71898"
"56.40000","-18.78346","-0.72204"
"56.50000","-18.81674","-0.72227"
"56.60000","-18.85029","-0.70947"
"56.70000","-18.88339","-0.71188"
"56.80000","-18.91688","-0.71754"
"56.90000","-18.95004","-0.72610"
"57.00000","-18.98367","-0.71192"
"57.10000","-19.01696","-0.69866"
"57.20000","-19.05026","-0.69231"
"57.30000","-19.08350","-0.69845"
"57.40000","-19.11690","-0.70048"
"57.50000","-19.15034","-0.69617"
"57.60000","-19.18375","-0.69311"
"57.70000","-19.21694","-0.69491"
"57.80000","-19.25016","-0.68603"
"57.90000","-19.28373","-0.69031"
"58.00000","-19.31692","-0.69855"
"58.10000","-19.35050","-0.70394"
"58.20000","-19.38360","-0.71543"
"58.30000","-19.41689","-0.70958"
"58.40000","-19.45018","-0.70555"
"58.50000","-19.48369","-0.70886"
"58.60000","-19.51698","-0.71013"
"58.70000","-19.55036","-0.70362"
"58.80000","-19.58353","-0.70915"
"58.90000","-19.61690","-0.70183"
"59.00000","-19.65017","-0.69426"
"59.10000","-19.68360","-0.69403"
"59.20000","-19.71696","-0.70752"
"59.30000","-19.75011","-0.70564"
"59.40000","-19.78352","-0.70325"
"59.50000","-19.81674","-0.69232"
"59.60000","-19.85035","-0.69309"
"59.70000","-19.88347","-0.70149"
"59.80000","-19.91680","-0.69768"
"59.90000","-19.94997","-0.70059"
"60.00000","-19.98354","-0.69113"
"60.05100","-20.00043","-0.66851"
"60.10200","-20.00518","-0.60278"
"60.20200","-19.97675","-0.64144"
"60.30200","-19.94049","-0.60277"
"60.40200","-19.90717","-0.57483"
"60.50200","-19.87358","-0.55744"
"60.60200","-19.84018","-0.54273"
"60.70200","-19.80677","-0.53003"
"60.80200","-19.77347","-0.52153"
"60.90200","-19.74033","-0.50280"
"61.00200","-19.70684","-0.48550"
"61.10200","-19.67358","-0.46312"
"61.20200","-19.64010","-0.45767"
"61.30200","-19.60708","-0.44752"
"61.40200","-19.57353","-0.44560"
"61.50200","-19.54045","-0.43245"
"61.60200","-19.50685","-0.41661"
"61.70200","-19.47366","-0.41499"
"61.80200","-19.44026","-0.41272"
"61.90200","-19.40707","-0.40961"
"62.00200","-19.37376","-0.41525"
"62.10200","-19.34042","-0.40797"
"62.20200","-19.30704","-0.40296"
"62.30200","-19.27369","-0.40332"
"62.40200","-19.24045","-0.40096"
"62.50200","-19.20706","-0.39691"
"62.60200","-19.17393","-0.38449"
"62.70200","-19.14027","-0.38043"
"62.80200","-19.10715","-0.36959"
"62.90200","-19.07369","-0.37724"
"63.00200","-19.04060","-0.38150"
"63.10200","-19.00699","-0.37977"
"63.20200","-18.97366","-0.37657"
"63.30200","-18.94018","-0.37404"
"63.40200","-18.90707","-0.37543"
"63.50200","-18.87362","-0.36658"
"63.60200","-18.84031","-0.36476"
"63.70200","-18.80680","-0.36667"
"63.80200","-18.77348","-0.35956"
"63.90200","-18.74027","-0.36475"
"64.00200","-18.70692","-0.36147"
"64.10200","-18.67365","-0.35532"
"64.20200","-18.64005","-0.37481"
"64.30200","-18.60690","-0.36702"
"64.40200","-18.57344","-0.36712"
"64.50200","-18.54040","-0.36477"
"64.60200","-18.50681","-0.34681"
"64.70200","-18.47359","-0.35217"
"64.80200","-18.44000","-0.36334"
"64.90200","-18.40686","-0.36666"
"65.00200","-18.37355","-0.37946"
"65.10200","-18.34025","-0.37041"
"65.20200","-18.30689","-0.35895"
"65.30200","-18.27347","-0.36259"
"65.40200","-18.24031","-0.36851"
"65.50200","-18.20688","-0.36121"
"65.60200","-18.17373","-0.35870"
"65.70200","-18.14018","-0.34786"
"65.80200","-18.10702","-0.33824"
"65.90200","-18.07359","-0.34559"
"66.00200","-18.04047","-0.34591"
"66.10200","-18.00707","-0.34310"
"66.20200","-17.97382","-0.34140"
"66.30200","-17.94031","-0.33750"
"66.40200","-17.90713","-0.34340"
"66.50200","-17.87373","-0.34878"
"66.60200","-17.84053","-0.33827"
"66.70200","-17.80710","-0.33817"
"66.80200","-17.77365","-0.32768"
"66.90200","-17.74041","-0.33745"
"67.00200","-17.70701","-0.34382"
"67.10200","-17.67387","-0.34377"
"67.20200","-17.64033","-0.35112"
"67.30200","-17.60704","-0.34806"
"67.40200","-17.57348","-0.34833"
"67.50200","-17.54042","-0.35522"
"67.60200","-17.50694","-0.35627"
"67.70200","-17.47371","-0.35111"
"67.80200","-17.44005","-0.34817"
"67.90200","-17.40693","-0.35717"
"68.00200","-17.37351","-0.35149"
"68.10200","-17.34031","-0.34639"
"68.20200","-17.30682","-0.34529"
"68.30200","-17.27342","-0.33868"
"68.40200","-17.24012","-0.34901"
"68.50200","-17.20682","-0.34739"
"68.60200","-17.17368","-0.34286"
"68.70200","-17.14016","-0.35263"
"68.80200","-17.10689","-0.34918"
"68.90200","-17.07334","-0.34604"
"69.00200","-17.04030","-0.34889"
"69.10200","-17.00685","-0.35038"
"69.20200","-16.97368","-0.36419"
"69.30200","-16.94014","-0.35143"
"69.40200","-16.90688","-0.34546"
"69.50200","-16.87357","-0.35447"
"69.60200","-16.84030","-0.35008"
"69.70200","-16.80699","-0.34895"
"69.80200","-16.77359","-0.35340"
"69.90200","-16.74027","-0.35797"
"70.00200","-16.70694","-0.35087"
"70.10200","-16.67377","-0.33987"
"70.20200","-16.64042","-0.33522"
"70.30200","-16.60714","-0.33274"
"70.40200","-16.57357","-0.34288"
"70.50200","-16.54049","-0.33810"
"70.60200","-16.50700","-0.34405"
"70.70200","-16.47396","-0.33821"
"70.80200","-16.44035","-0.33435"
"70.90200","-16.40709","-0.33537"
"71.00200","-16.37362","-0.33769"
"71.10200","-16.34050","-0.33069"
"71.20200","-16.30707","-0.33273"
"71.30200","-16.27374","-0.34430"
"71.40200","-16.24021","-0.35148"
"71.50200","-16.20692","-0.34957"
"71.60200","-16.17367","-0.34833"
"71.70200","-16.14044","-0.35449"
"71.80200","-16.10713","-0.35389"
"71.90200","-16.07340","-0.35464"
"72.00200","-16.04026","-0.35141"
"72.10200","-16.00677","-0.35923"
"72.20200","-15.97371","-0.36241"
"72.30200","-15.94018","-0.36525"
"72.40200","-15.90682","-0.36012"
"72.50200","-15.87339","-0.35204"
"72.60200","-15.84019","-0.34326"
"72.70200","-15.80695","-0.33968"
"72.80200","-15.77353","-0.34347"
"72.90200","-15.74017","-0.34049"
"73.00200","-15.70661","-0.33396"
"73.10200","-15.67354","-0.33042"
"73.20200","-15.64014","-0.33410"
"73.30200","-15.60704","-0.33436"
"73.40200","-15.57343","-0.34229"
"73.50200","-15.54023","-0.32329"
"73.60200","-15.50692","-0.32967"
"73.70200","-15.47373","-0.33277"
"73.80200","-15.44030","-0.33291"
"73.90200","-15.40704","-0.33106"
"74.00200","-15.37360","-0.32897"
"74.10200","-15.34036","-0.31761"
"74.20200","-15.30703","-0.31918"
"74.30200","-15.27382","-0.32510"
"74.40200","-15.24042","-0.32934"
"74.50200","-15.20700","-0.33253"
"74.60200","-15.17385","-0.32863"
"74.70200","-15.14040","-0.31706"
"74.80200","-15.10722","-0.32296"
"74.90200","-15.07368","-0.31896"
"75.00200","-15.04048","-0.31271"
"75.10200","-15.00693","-0.31223"
"75.20200","-14.97387","-0.29651"
"75.30200","-14.94036","-0.30566"
"75.40200","-14.90712","-0.31201"
"75.50200","-14.87350","-0.31507"
"75.60200","-14.84023","-0.31333"
"75.70200","-14.80689","-0.32022"
"75.80200","-14.77365","-0.30848"
"75.90200","-14.74029","-0.30894"
"76.00200","-14.70678","-0.32617"
"76.10200","-14.67358","-0.32368"
"76.20200","-14.64012","-0.32040"
"76.30200","-14.60705","-0.31214"
"76.40200","-14.57349","-0.32437"
"76.50200","-14.54018","-0.32770"
"76.60200","-14.50669","-0.31659"
"76.70200","-14.47360","-0.31154"
"76.80200","-14.44020","-0.31450"
"76.90200","-14.40690","-0.31825"
"77.00200","-14.37342","-0.32163"
"77.10200","-14.34010","-0.31768"
"77.20200","-14.30681","-0.31398"
"77.30200","-14.27360","-0.30906"
"77.40200","-14.24030","-0.31013"
"77.50200","-14.20679","-0.31303"
"77.60200","-14.17354","-0.32165"
"77.70200","-14.14021","-0.32458"
"77.80200","-14.10707","-0.31988"
"77.90200","-14.07362","-0.32125"
"78.00200","-14.04041","-0.31690"
"78.10200","-14.00690","-0.31507"
"78.20200","-13.97381","-0.31906"
"78.30200","-13.94030","-0.30882"
"78.40200","-13.90724","-0.31336"
"78.50200","-13.87369","-0.31957"
"78.60200","-13.84036","-0.31199"
"78.70200","-13.80708","-0.32261"
"78.80200","-13.77374","-0.30616"
"78.90200","-13.74056","-0.30845"
"79.00200","-13.70705","-0.32063"
"79.10200","-13.67376","-0.31425"
"79.20200","-13.64028","-0.32778"
"79.30200","-13.60718","-0.31736"
"79.40200","-13.57371","-0.32543"
"79.50200","-13.54046","-0.32842"
"79.60200","-13.50677","-0.33177"
"79.70200","-13.47362","-0.32948"
"79.80200","-13.44021","-0.32905"
"79.90200","-13.40704","-0.32590"
"80.00200","-13.37359","-0.32230"
"80.10200","-13.34015","-0.32633"
"80.20200","-13.30685","-0.32714"
"80.30200","-13.27348","-0.33153"
"80.40200","-13.24030","-0.32999"
"80.50200","-13.20679","-0.33143"
"80.60200","-13.17353","-0.33906"
"80.70200","-13.14005","-0.32546"
"80.80200","-13.10693","-0.32193"
"80.90200","-13.07355","-0.32552"
"81.00200","-13.04031","-0.31834"
"81.10200","-13.00671","-0.32345"
"81.20200","-12.97352","-0.32912"
"81.30200","-12.94009","-0.31643"
"81.40200","-12.90699","-0.31961"
"81.50200","-12.87356","-0.32903"
"81.60200","-12.84019","-0.32622"
"81.70200","-12.80686","-0.33559"
"81.80200","-12.77360","-0.32773"
"81.90200","-12.74038","-0.31930"
"82.00200","-12.70698","-0.32283"
"82.10200","-12.67370","-0.31912"
"82.20200","-12.64020","-0.32429"
"82.30200","-12.60714","-0.32490"
"82.40200","-12.57365","-0.31891"
"82.50200","-12.54065","-0.30836"
"82.60200","-12.50699","-0.32100"
"82.70200","-12.47379","-0.32418"
"82.80200","-12.44034","-0.32341"
"82.90200","-12.40716","-0.31887"
"83.00200","-12.37370","-0.32037"
"83.10200","-12.34045","-0.32161"
"83.20200","-12.30700","-0.31878"
"83.30200","-12.27367","-0.31985"
"83.40200","-12.24046","-0.32149"
"83.50200","-12.20703","-0.31862"
"83.60200","-12.17376","-0.31548"
"83.70200","-12.14011","-0.31336"
"83.80200","-12.10704","-0.31800"
"83.90200","-12.07355","-0.32208"
"84.00200","-12.04045","-0.31241"
"84.10200","-12.00687","-0.30659"
"84.20200","-11.97356","-0.30251"
"84.30200","-11.94012","-0.30763"
"84.40200","-11.90690","-0.31118"
"84.50200","-11.87353","-0.29255"
"84.60200","-11.84023","-0.28288"
"84.70200","-11.80675","-0.28895"
"84.80200","-11.77346","-0.28443"
"84.90200","-11.74021","-0.28196"
"85.00200","-11.70690","-0.27462"
"85.10200","-11.67362","-0.27748"
"85.20200","-11.64009","-0.28388"
"85.30200","-11.60689","-0.28391"
"85.40200","-11.57344","-0.27228"
"85.50200","-11.54038","-0.28131"
"85.60200","-11.50687","-0.27331"
"85.70200","-11.47362","-0.27240"
"85.80200","-11.44011","-0.27530"
"85.90200","-11.40707","-0.27779"
"86.00200","-11.37364","-0.28555"
"86.10200","-11.34042","-0.27622"
"86.20200","-11.30697","-0.27528"
"86.30200","-11.27357","-0.27038"
"86.40200","-11.24040","-0.26772"
"86.50200","-11.20695","-0.26725"
"86.60200","-11.17396","-0.25988"
"86.70200","-11.14030","-0.25075"
"86.80200","-11.10719","-0.25323"
"86.90200","-11.07362","-0.24642"
"87.00200","-11.04059","-0.24958"
"87.10200","-11.00704","-0.25143"
"87.20200","-10.97387","-0.25090"
"87.30200","-10.94022","-0.25216"
"87.40200","-10.90705","-0.25296"
"87.50200","-10.87368","-0.25945"
"87.60200","-10.84042","-0.26668"
"87.70200","-10.80702","-0.28094"
"87.80200","-10.77357","-0.28297"
"87.90200","-10.74030","-0.29075"
"88.00200","-10.70686","-0.28201"
"88.10200","-10.67371","-0.26914"
"88.20200","-10.64022","-0.27071"
"88.30200","-10.60690","-0.28513"
"88.40200","-10.57337","-0.29076"
"88.50200","-10.54030","-0.28687"
"88.60200","-10.50685","-0.28408"
"88.70200","-10.47367","-0.28195"
"88.80200","-10.44008","-0.28416"
"88.90200","-10.40687","-0.27603"
"89.00200","-10.37347","-0.26965"
"89.10200","-10.34023","-0.28015"
"89.20200","-10.30689","-0.28493"
"89.30200","-10.27345","-0.28617"
"89.40200","-10.24015","-0.28704"
"89.50200","-10.20677","-0.28301"
"89.60200","-10.17370","-0.27321"
"89.70200","-10.14020","-0.27513"
"89.80200","-10.10696","-0.26900"
"89.90200","-10.07343","-0.27783"
"90.00200","-10.04047","-0.27940"
"90.10200","-10.00695","-0.27457"
"90.20200","-9.97383","-0.28546"
"90.30200","-9.94024","-0.27951"
"90.40200","-9.90701","-0.27765"
"90.50200","-9.87369","-0.26541"
"90.60200","-9.84042","-0.26482"
"90.70200","-9.80717","-0.26437"
"90.80200","-9.77370","-0.26116"
"90.90200","-9.74042","-0.25476"
"91.00200","-9.70703","-0.25146"
"91.10200","-9.67389","-0.24830"
"91.20200","-9.64035","-0.25230"
"91.30200","-9.60718","-0.25242"
"91.40200","-9.57360","-0.25390"
"91.50200","-9.54044","-0.24792"
"91.60200","-9.50696","-0.24037"
"91.70200","-9.47381","-0.24803"
"91.80200","-9.44027","-0.24129"
"91.90200","-9.40688","-0.23347"
"92.00200","-9.37352","-0.23548"
"92.10200","-9.34025","-0.24574"
"92.20200","-9.30700","-0.24611"
"92.30200","-9.27357","-0.23526"
"92.40200","-9.24017","-0.24442"
"92.50200","-9.20673","-0.24277"
"92.60200","-9.17360","-0.23643"
"92.70200","-9.14019","-0.23617"
"92.80200","-9.10697","-0.24028"
"92.90200","-9.07336","-0.25294"
"93.00200","-9.04025","-0.23323"
"93.10200","-9.00681","-0.23054"
"93.20200","-8.97370","-0.23499"
"93.30200","-8.94019","-0.24698"
"93.40200","-8.90686","-0.24660"
"93.50200","-8.87344","-0.23891"
"93.60200","-8.84017","-0.24259"
"93.70200","-8.80695","-0.24396"
"93.80200","-8.77357","-0.24343"
"93.90200","-8.74028","-0.24066"
"94.00200","-8.70681","-0.24573"
"94.10200","-8.67378","-0.24366"
"94.20200","-8.64023","-0.23735"
"94.30200","-8.60715","-0.23326"
"94.40200","-8.57356","-0.24311"
"94.50200","-8.54045","-0.22532"
"94.60200","-8.50698","-0.22798"
"94.70200","-8.47382","-0.23201"
"94.80200","-8.44039","-0.22811"
"94.90200","-8.40711","-0.22642"
"95.00200","-8.37363","-0.22829"
"95.10200","-8.34047","-0.22168"
"95.20200","-8.30707","-0.23154"
"95.30200","-8.27379","-0.22838"
"95.40200","-8.24045","-0.22317"
"95.50200","-8.20688","-0.22646"
"95.60200","-8.17372","-0.24092"
"95.70200","-8.14023","-0.23633"
"95.80200","-8.10714","-0.22935"
"95.90200","-8.07359","-0.24673"
"96.00200","-8.04030","-0.23244"
"96.10200","-8.00678","-0.24028"
"96.20200","-7.97366","-0.23544"
"96.30200","-7.94024","-0.23765"
"96.40200","-7.90701","-0.23740"
"96.50200","-7.87342","-0.23009"
"96.60200","-7.84016","-0.22446"
"96.70200","-7.80686","-0.23725"
"96.80200","-7.77360","-0.22365"
"96.90200","-7.74027","-0.21328"
"97.00200","-7.70671","-0.22495"
"97.10200","-7.67362","-0.22300"
"97.20200","-7.64011","-0.23124"
"97.30200","-7.60701","-0.23034"
"97.40200","-7.57355","-0.21880"
"97.50200","-7.54023","-0.21582"
"97.60200","-7.50672","-0.20644"
"97.70200","-7.47365","-0.21374"
"97.80200","-7.44024","-0.21316"
"97.90200","-7.40700","-0.21788"
"98.00200","-7.37350","-0.21029"
"98.10200","-7.34020","-0.20096"
"98.20200","-7.30702","-0.21344"
"98.30200","-7.27368","-0.22806"
"98.40200","-7.24044","-0.22559"
"98.50200","-7.20695","-0.20482"
"98.60200","-7.17369","-0.20855"
"98.70200","-7.14031","-0.21354"
"98.80200","-7.10719","-0.20873"
"98.90200","-7.07375","-0.20176"
"99.00200","-7.04052","-0.20697"
"99.10200","-7.00694","-0.20194"
"99.20200","-6.97383","-0.20340"
"99.30200","-6.94036","-0.20369"
"99.40200","-6.90715","-0.18961"
"99.50200","-6.87366","-0.21083"
"99.60200","-6.84027","-0.22369"
"99.70200","-6.80696","-0.22213"
"99.80200","-6.77364","-0.22393"
"99.90200","-6.74039","-0.21422"
"100.00200","-6.70694","-0.22077"
"100.10200","-6.67358","-0.22035"
"100.20200","-6.64010","-0.22623"
"100.30200","-6.60698","-0.23278"
"100.40200","-6.57361","-0.22085"
"100.50200","-6.54037","-0.21210"
"100.60200","-6.50676","-0.20715"
"100.70200","-6.47355","-0.20892"
"100.80200","-6.44015","-0.21200"
"100.90200","-6.40703","-0.20696"
"101.00200","-6.37350","-0.21213"
"101.10200","-6.34013","-0.21861"
"101.20200","-6.30680","-0.20870"
"101.30200","-6.27350","-0.21371"
"101.40200","-6.24030","-0.19978"
"101.50200","-6.20686","-0.20412"
"101.60200","-6.17357","-0.21715"
"101.70200","-6.14006","-0.22522"
"101.80200","-6.10698","-0.20523"
"101.90200","-6.07358","-0.21520"
"102.00200","-6.04042","-0.22109"
"102.10200","-6.00676","-0.23074"
"102.20200","-5.97363","-0.22477"
"102.30200","-5.94022","-0.20517"
"102.40200","-5.90711","-0.19709"
"102.50200","-5.87366","-0.18370"
"102.60200","-5.84039","-0.18388"
"102.70200","-5.80696","-0.19515"
"102.80200","-5.77376","-0.18076"
"102.90200","-5.74040","-0.17191"
"103.00200","-5.70716","-0.15776"
"103.10200","-5.67373","-0.15411"
"103.20200","-5.64026","-0.16698"
"103.30200","-5.60708","-0.17927"
"103.40200","-5.57367","-0.17176"
"103.50200","-5.54053","-0.16507"
"103.60200","-5.50719","-0.17293"
"103.70200","-5.47376","-0.18819"
"103.80200","-5.44019","-0.19511"
"103.90200","-5.40708","-0.19659"
"104.00200","-5.37369","-0.19568"
"104.10200","-5.34034","-0.18596"
"104.20200","-5.30681","-0.18985"
"104.30200","-5.27351","-0.18214"
"104.40200","-5.24024","-0.17353"
"104.50200","-5.20693","-0.17155"
"104.60200","-5.17372","-0.17473"
"104.70200","-5.14006","-0.16846"
"104.80200","-5.10693","-0.16948"
"104.90200","-5.07342","-0.16950"
"105.00200","-5.04044","-0.16162"
"105.10200","-5.00682","-0.17428"
"105.20200","-4.97356","-0.17218"
"105.30200","-4.94009","-0.16549"
"105.40200","-4.90694","-0.16537"
"105.50200","-4.87356","-0.16643"
"105.60200","-4.84027","-0.16635"
"105.70200","-4.80682","-0.17230"
"105.80200","-4.77346","-0.16553"
"105.90200","-4.74030","-0.15863"
"106.00200","-4.70694","-0.16312"
"106.10200","-4.67375","-0.16894"
"106.20200","-4.64014","-0.17460"
"106.30200","-4.60701","-0.16035"
"106.40200","-4.57362","-0.15641"
"106.50200","-4.54053","-0.14510"
"106.60200","-4.50695","-0.14138"
"106.70200","-4.47371","-0.14630"
"106.80200","-4.44022","-0.15699"
"106.90200","-4.40711","-0.15678"
"107.00200","-4.37368","-0.14596"
"107.10200","-4.34052","-0.14424"
"107.20200","-4.30702","-0.14131"
"107.30200","-4.27364","-0.14793"
"107.40200","-4.24043","-0.14864"
"107.50200","-4.20704","-0.15303"
"107.60200","-4.17378","-0.15388"
"107.70200","-4.14024","-0.14230"
"107.80200","-4.10701","-0.14749"
"107.90200","-4.07351","-0.15046"
"108.00200","-4.04045","-0.15142"
"108.10200","-4.00694","-0.16274"
"108.20200","-3.97377","-0.14706"
"108.30200","-3.94006","-0.13648"
"108.40200","-3.90694","-0.14484"
"108.50200","-3.87350","-0.14628"
"108.60200","-3.84031","-0.14508"
"108.70200","-3.80692","-0.14971"
"108.80200","-3.77347","-0.15130"
"108.90200","-3.74022","-0.13931"
"109.00200","-3.70681","-0.13732"
"109.10200","-3.67377","-0.13868"
"109.20200","-3.64012","-0.13265"
"109.30200","-3.60694","-0.14060"
"109.40200","-3.57343","-0.13798"
"109.50200","-3.54031","-0.13414"
"109.60200","-3.50688","-0.14426"
"109.70200","-3.47369","-0.13749"
"109.80200","-3.44010","-0.13602"
"109.90200","-3.40695","-0.13398"
"110.00200","-3.37353","-0.12855"
"110.10200","-3.34041","-0.12056"
"110.20200","-3.30696","-0.13103"
"110.30200","-3.27353","-0.12894"
"110.40200","-3.24030","-0.12556"
"110.50200","-3.20699","-0.12366"
"110.60200","-3.17376","-0.12317"
"110.70200","-3.14036","-0.13643"
"110.80200","-3.10708","-0.12997"
"110.90200","-3.07355","-0.11280"
"111.00200","-3.04048","-0.09958"
"111.10200","-3.00700","-0.10322"
"111.20200","-2.97387","-0.10560"
"111.30200","-2.94032","-0.10642"
"111.40200","-2.90696","-0.09853"
"111.50200","-2.87362","-0.09502"
"111.60200","-2.84040","-0.08830"
"111.70200","-2.80706","-0.08373"
"111.80200","-2.77364","-0.08838"
"111.90200","-2.74029","-0.09657"
"112.00200","-2.70683","-0.09845"
"112.10200","-2.67376","-0.09410"
"112.20200","-2.64030","-0.09205"
"112.30200","-2.60703","-0.08760"
"112.40200","-2.57338","-0.09579"
"112.50200","-2.54035","-0.09663"
"112.60200","-2.50682","-0.08279"
"112.70200","-2.47375","-0.08030"
"112.80200","-2.44024","-0.07402"
"112.90200","-2.40682","-0.06985"
"113.00200","-2.37346","-0.06805"
"113.10200","-2.34020","-0.06363"
"113.20200","-2.30696","-0.06716"
"113.30200","-2.27351","-0.06510"
"113.40200","-2.24020","-0.05500"
"113.50200","-2.20681","-0.04588"
"113.60200","-2.17369","-0.05653"
"113.70200","-2.14020","-0.05373"
"113.80200","-2.10701","-0.04726"
"113.90200","-2.07347","-0.04541"
"114.00200","-2.04029","-0.03332"
"114.10200","-2.00685","-0.03202"
"114.20200","-1.97381","-0.03170"
"114.30200","-1.94029","-0.03275"
"114.40200","-1.90697","-0.02404"
"114.50200","-1.87356","-0.01810"
"114.60200","-1.84040","-0.00783"
"114.70200","-1.80704","-0.00401"
"114.80200","-1.77367","0.00214"
"114.90200","-1.74028","0.00059"
"115.00200","-1.70692","0.00434"
"115.10200","-1.67380","0.01579"
"115.20200","-1.64030","0.01511"
"115.30200","-1.60723","0.02054"
"115.40200","-1.57356","0.02129"
"115.50200","-1.54038","0.02215"
"115.60200","-1.50689","0.02808"
"115.70200","-1.47383","0.03634"
"115.80200","-1.44029","0.03321"
"115.90200","-1.40707","0.01954"
"116.00200","-1.37347","0.01988"
"116.10200","-1.34028","0.03678"
"116.20200","-1.30700","0.02856"
"116.30200","-1.27364","0.03013"
"116.40200","-1.24029","0.02777"
"116.50200","-1.20677","0.03146"
"116.60200","-1.17365","0.03961"
"116.70200","-1.14016","0.03020"
"116.80200","-1.10713","0.03471"
"116.90200","-1.07346","0.03969"
"117.00200","-1.04032","0.03118"
"117.10200","-1.00676","0.03575"
"117.20200","-0.97367","0.03498"
"117.30200","-0.94025","0.03530"
"117.40200","-0.90695","0.03372"
"117.50200","-0.87346","0.03108"
"117.60200","-0.84022","0.03038"
"117.70200","-0.80691","0.02886"
"117.80200","-0.77359","0.04051"
"117.90200","-0.74036","0.02765"
"118.00200","-0.70680","0.02583"
"118.10200","-0.67363","0.02643"
"118.20200","-0.64016","0.02308"
"118.30200","-0.60716","0.03326"
"118.40200","-0.57357","0.02803"
"118.50200","-0.54035","0.03443"
"118.60200","-0.50687","0.04261"
"118.70200","-0.47382","0.03950"
"118.80200","-0.44034","0.04083"
"118.90200","-0.40714","0.03388"
"119.00200","-0.37358","0.03549"
"119.10200","-0.34034","0.03340"
"119.20200","-0.30702","0.03700"
"119.30200","-0.27369","0.03304"
"119.40200","-0.24045","0.03790"
"119.50200","-0.20696","0.02722"
"119.60200","-0.17374","0.03726"
"119.70200","-0.14027","0.03700"
"119.80200","-0.10714","0.03199"
"119.90200","-0.07364","0.03094"
"120.00200","-0.04044","0.03705"
"120.10200","-0.00675","0.03645"
"120.12300","0.00022","0.00383"